#VRML_SIM R2023b utf8
# license: Apache License 2.0
# license url: http://www.apache.org/licenses/LICENSE-2.0
# This is a proto file for Webots for the Machine.SLDASM
# Extracted from: D:\Sem 3 - E22\E22\DP\Our\2.0\Drawing\Machine\URDF\Machine.SLDASM\urdf\Machine.SLDASM.urdf

PROTO Machine.SLDASM [
  field  SFVec3f     translation     0 0 0
  field  SFRotation  rotation        0 0 1 0
  field  SFString    name            "Machine.SLDASM"  # Is `Robot.name`.
  field  SFString    controller      "void"            # Is `Robot.controller`.
  field  MFString    controllerArgs  []                # Is `Robot.controllerArgs`.
  field  SFString    customData      ""                # Is `Robot.customData`.
  field  SFBool      supervisor      FALSE             # Is `Robot.supervisor`.
  field  SFBool      synchronization TRUE              # Is `Robot.synchronization`.
  field  SFBool      selfCollision   FALSE             # Is `Robot.selfCollision`.
]
{
  Robot {
    translation IS translation
    rotation IS rotation
    controller IS controller
    controllerArgs IS controllerArgs
    customData IS customData
    supervisor IS supervisor
    synchronization IS synchronization
    selfCollision IS selfCollision
    children [
      Shape {
        appearance DEF base_link_material PBRAppearance {
          roughness 1.000000
          metalness 0
        }
        geometry DEF base_link Mesh {
          url "D:\Sem 3 - E22\E22\DP\Our\2.0\Drawing\Machine\URDF/Machine.SLDASM/meshes/base_link.STL"
        }
      }
      HingeJoint {
        jointParameters HingeJointParameters {
          axis 0.000000 0.000000 0.000000
          anchor -0.191330 -0.504020 0.312300
        }
        device [
          RotationalMotor {
            name "FR"
            maxTorque 10000
          }
          PositionSensor {
            name "FR_sensor"
          }
        ]
        endPoint Solid {
          translation -0.191330 -0.504020 0.312300
          rotation 0.707105 -0.707108 0.000003 3.141598
          children [
            Shape {
              appearance DEF FR_material PBRAppearance {
                baseColor 0.792157 0.819608 0.933333
                roughness 1.000000
                metalness 0
              }
              geometry DEF FR Mesh {
                url "D:\Sem 3 - E22\E22\DP\Our\2.0\Drawing\Machine\URDF/Machine.SLDASM/meshes/FR.STL"
              }
            }
          ]
          name "FR"
          boundingObject USE FR
          physics Physics {
            density -1
            mass 0.295538
            centerOfMass [ -0.001156 -0.032558 -0.000375 ]
            inertiaMatrix [
              1.225096e-04 1.218801e-04 1.224328e-04
              -5.687045e-12 -1.975564e-10 -8.407247e-07
            ]
          }
        }
      }
      HingeJoint {
        jointParameters HingeJointParameters {
          axis 0.000000 0.000000 0.000000
          anchor -0.191330 -0.242210 0.312300
        }
        device [
          RotationalMotor {
            name "BR"
            maxTorque 10000
          }
          PositionSensor {
            name "BR_sensor"
          }
        ]
        endPoint Solid {
          translation -0.191330 -0.242210 0.312300
          rotation 0.707105 -0.707108 0.000003 3.141598
          children [
            Shape {
              appearance DEF BR_material PBRAppearance {
                baseColor 0.792157 0.819608 0.933333
                roughness 1.000000
                metalness 0
              }
              geometry DEF BR Mesh {
                url "D:\Sem 3 - E22\E22\DP\Our\2.0\Drawing\Machine\URDF/Machine.SLDASM/meshes/BR.STL"
              }
            }
          ]
          name "BR"
          boundingObject USE BR
          physics Physics {
            density -1
            mass 0.295538
            centerOfMass [ -0.000263 -0.032558 -0.000375 ]
            inertiaMatrix [
              1.225096e-04 1.218801e-04 1.224328e-04
              -5.687045e-12 -1.975564e-10 -8.407247e-07
            ]
          }
        }
      }
      HingeJoint {
        jointParameters HingeJointParameters {
          axis 0.000000 0.000000 0.000000
          anchor 0.350690 -0.242210 0.312300
        }
        device [
          RotationalMotor {
            name "BL"
            maxTorque 10000
          }
          PositionSensor {
            name "BL_sensor"
          }
        ]
        endPoint Solid {
          translation 0.350690 -0.242210 0.312300
          rotation 0.707105 -0.707108 0.000003 3.141598
          children [
            Shape {
              appearance DEF BL_material PBRAppearance {
                baseColor 0.792157 0.819608 0.933333
                roughness 1.000000
                metalness 0
              }
              geometry DEF BL Mesh {
                url "D:\Sem 3 - E22\E22\DP\Our\2.0\Drawing\Machine\URDF/Machine.SLDASM/meshes/BL.STL"
              }
            }
          ]
          name "BL"
          boundingObject USE BL
          physics Physics {
            density -1
            mass 0.295538
            centerOfMass [ 0.001368 0.034323 -0.000375 ]
            inertiaMatrix [
              1.225058e-04 1.218838e-04 1.224328e-04
              -4.251955e-07 7.119538e-09 8.406977e-07
            ]
          }
        }
      }
      HingeJoint {
        jointParameters HingeJointParameters {
          axis 0.000000 0.000000 0.000000
          anchor 0.350690 -0.504020 0.312300
        }
        device [
          RotationalMotor {
            name "FL"
            maxTorque 10000
          }
          PositionSensor {
            name "FL_sensor"
          }
        ]
        endPoint Solid {
          translation 0.350690 -0.504020 0.312300
          rotation 0.707105 -0.707108 0.000003 3.141598
          children [
            Shape {
              appearance DEF FL_material PBRAppearance {
                baseColor 0.792157 0.819608 0.933333
                roughness 1.000000
                metalness 0
              }
              geometry DEF FL Mesh {
                url "D:\Sem 3 - E22\E22\DP\Our\2.0\Drawing\Machine\URDF/Machine.SLDASM/meshes/FL.STL"
              }
            }
          ]
          name "FL"
          boundingObject USE FL
          physics Physics {
            density -1
            mass 0.295538
            centerOfMass [ 0.000468 0.032498 -0.000375 ]
            inertiaMatrix [
              1.225058e-04 1.218838e-04 1.224328e-04
              -4.251955e-07 7.119538e-09 8.406977e-07
            ]
          }
        }
      }
      HingeJoint {
        jointParameters HingeJointParameters {
          axis 0.000000 0.000000 0.000000
          anchor -0.020433 -0.550930 0.355170
        }
        device [
          RotationalMotor {
            name "Roller"
            maxTorque 10000
          }
          PositionSensor {
            name "Roller_sensor"
          }
        ]
        endPoint Solid {
          translation -0.020433 -0.550930 0.355170
          rotation 1.000000 0.000000 0.000000 1.570800
          children [
            Shape {
              appearance DEF Roller_material PBRAppearance {
                baseColor 0.792157 0.819608 0.933333
                roughness 1.000000
                metalness 0
              }
              geometry DEF Roller Mesh {
                url "D:\Sem 3 - E22\E22\DP\Our\2.0\Drawing\Machine\URDF/Machine.SLDASM/meshes/Roller.STL"
              }
            }
          ]
          name "Roller"
          boundingObject USE Roller
          physics Physics {
            density -1
            mass 0.553667
            centerOfMass [ 0.177062 0.000115 0.000803 ]
            inertiaMatrix [
              7.947128e-04 4.481073e-03 4.481130e-03
              -8.755284e-09 1.036442e-16 9.744233e-18
            ]
          }
        }
      }
      HingeJoint {
        jointParameters HingeJointParameters {
          axis 0.000000 0.000000 0.000000
          anchor -0.018804 -0.339680 0.271390
        }
        device [
          RotationalMotor {
            name "MR"
            maxTorque 10000
          }
          PositionSensor {
            name "MR_sensor"
          }
        ]
        endPoint Solid {
          translation -0.018804 -0.339680 0.271390
          rotation 1.000000 0.000000 0.000000 1.570800
          children [
            Shape {
              appearance DEF MR_material PBRAppearance {
                baseColor 0.498039 0.498039 0.498039
                roughness 1.000000
                metalness 0
              }
              geometry DEF MR Mesh {
                url "D:\Sem 3 - E22\E22\DP\Our\2.0\Drawing\Machine\URDF/Machine.SLDASM/meshes/MR.STL"
              }
            }
          ]
          name "MR"
          boundingObject USE MR
          physics Physics {
            density -1
            mass 0.330345
            centerOfMass [ 0.000299 0.022963 0.000209 ]
            inertiaMatrix [
              3.645130e-04 6.171744e-04 3.645700e-04
              8.755284e-09 5.716212e-22 1.099968e-21
            ]
          }
        }
      }
      HingeJoint {
        jointParameters HingeJointParameters {
          axis 0.000000 0.000000 0.000000
          anchor 0.172750 -0.339510 0.271310
        }
        device [
          RotationalMotor {
            name "ML"
            maxTorque 10000
          }
          PositionSensor {
            name "ML_sensor"
          }
        ]
        endPoint Solid {
          translation 0.172750 -0.339510 0.271310
          rotation 1.000000 0.000000 0.000000 1.570800
          children [
            Shape {
              appearance DEF ML_material PBRAppearance {
                baseColor 0.498039 0.498039 0.498039
                roughness 1.000000
                metalness 0
              }
              geometry DEF ML Mesh {
                url "D:\Sem 3 - E22\E22\DP\Our\2.0\Drawing\Machine\URDF/Machine.SLDASM/meshes/ML.STL"
              }
            }
          ]
          name "ML"
          boundingObject USE ML
          physics Physics {
            density -1
            mass 0.330345
            centerOfMass [ -0.000484 0.022427 -0.000085 ]
            inertiaMatrix [
              3.645130e-04 6.171744e-04 3.645700e-04
              -8.755284e-09 1.334870e-22 2.194704e-21
            ]
          }
        }
      }
    ]
    name IS name
    boundingObject USE base_link
    physics Physics {
      density -1
      mass 8.997754
      centerOfMass [ 0.079047 0.350118 0.507466 ]
      inertiaMatrix [
        4.156311e-02 1.641227e-01 1.473912e-01
        -2.248084e-06 8.796538e-06 -4.672792e-04
      ]
    }
  }
}
